Workbook

Sheet Instructions
B2: Business Sales & Expense Tracker
B3: Auto-calculating dashboard — just enter your data, everything else updates itself
B5: How to use this sheet
B6: 1. Go to the 'Sales Entry' tab and add one row per sale (date, product, quantity, price).
B7: 2. Go to the 'Expense Entry' tab and add one row per expense (date, category, amount).
B8: 3. Open the 'Dashboard' tab — totals, profit, and monthly summary update automatically.
B9: 4. Do not edit cells with black formula text (columns marked 'Auto') — they calculate on their own.
B10: 5. Only type in cells shown in blue — those are your input cells.
B12: Tips
B13: - Use the dropdown in the Category column to keep expense names consistent.
B14: - The Dashboard automatically pulls the latest numbers — no manual updating needed.
B15: - You can add as many rows as you like; formulas are already extended to row 500.
... B25: a monthly sales bar chart and an expense category pie chart. Both update automatically.

Sheet Product List
A1: Product Name | B1: Default Price (₹) | D1: Add your product names & prices here.
A2: Notebook Set | B2: 150 | D2: This list feeds the dropdown in Sales Entry.
A3: Water Bottle | B3: 250
A4: Backpack | B4: 900
A5: Pen Pack | B5: 60

Sheet Sales Entry
A1: Date | B1: Product Name | C1: Quantity Sold | D1: Price per Unit (₹) | E1: Total Sale (₹) [Auto] | F1: Custom Field (optional)
A2: 46175 | B2: Notebook Set | C2: 10 | D2: 150 | E2: =IF(AND(C2<>"",D2<>""),C2*D2,"") -> 1500
A3: 46178 | B3: Water Bottle | C3: 6 | D3: 250 | E3: =IF(AND(C3<>"",D3<>""),C3*D3,"") -> 1500
A4: 46185 | B4: Backpack | C4: 3 | D4: 900 | E4: =IF(AND(C4<>"",D4<>""),C4*D4,"") -> 2700
A5: 46193 | B5: Notebook Set | C5: 8 | D5: 150 | E5: =IF(AND(C5<>"",D5<>""),C5*D5,"") -> 1200
A6: 46201 | B6: Pen Pack | C6: 15 | D6: 60 | E6: =IF(AND(C6<>"",D6<>""),C6*D6,"") -> 900
A7: 46206 | B7: Backpack | C7: 2 | D7: 900 | E7: =IF(AND(C7<>"",D7<>""),C7*D7,"") -> 1800
A8: 46211 | B8: Water Bottle | C8: 10 | D8: 250 | E8: =IF(AND(C8<>"",D8<>""),C8*D8,"") -> 2500
A9: 46218 | B9: Notebook Set | C9: 12 | D9: 150 | E9: =IF(AND(C9<>"",D9<>""),C9*D9,"") -> 1800
A10: 46206 | B10: Notebook Set | C10: 4 | D10: 150 | E10: =IF(AND(C10<>"",D10<>""),C10*D10,"") -> 600
A11: 46206 | B11: Water Bottle | C11: 2 | D11: 250 | E11: =IF(AND(C11<>"",D11<>""),C11*D11,"") -> 500
E12: =IF(AND(C12<>"",D12<>""),C12*D12,"")
E13: =IF(AND(C13<>"",D13<>""),C13*D13,"")
E14: =IF(AND(C14<>"",D14<>""),C14*D14,"")
E15: =IF(AND(C15<>"",D15<>""),C15*D15,"")
E16: =IF(AND(C16<>"",D16<>""),C16*D16,"")
E17: =IF(AND(C17<>"",D17<>""),C17*D17,"")
E18: =IF(AND(C18<>"",D18<>""),C18*D18,"")
E19: =IF(AND(C19<>"",D19<>""),C19*D19,"")
E20: =IF(AND(C20<>"",D20<>""),C20*D20,"")
E21: =IF(AND(C21<>"",D21<>""),C21*D21,"")
E22: =IF(AND(C22<>"",D22<>""),C22*D22,"")
E23: =IF(AND(C23<>"",D23<>""),C23*D23,"")
... E500: =IF(AND(C500<>"",D500<>""),C500*D500,"")

Sheet Expense Entry
A1: Date | B1: Category | C1: Description | D1: Amount (₹) | E1: Custom Field (optional)
A2: 46174 | B2: Rent | C2: Shop monthly rent | D2: 5000
A3: 46183 | B3: Inventory/Stock | C3: Stock purchase - notebooks | D3: 3000
A4: 46191 | B4: Marketing | C4: Instagram promotion | D4: 800
A5: 46198 | B5: Utilities | C5: Electricity bill | D5: 1200
A6: 46204 | B6: Rent | C6: Shop monthly rent | D6: 5000
A7: 46208 | B7: Transport | C7: Delivery charges | D7: 600

Sheet Dashboard
B2: Business Dashboard | H2: Today's Sales Snapshot
B3: Auto-updates from Sales Entry and Expense Entry tabs | H3: ="Auto-updates for "&TEXT(TODAY(),"DD-MMM-YYYY") -> Auto-updates for 03-Jul-2026
B5: Total Sales (₹) | C5: =SUM('Sales Entry'!E2:E500) -> 15000 | H5: Product | I5: Qty Sold Today | J5: Revenue Today (₹)
B6: Total Expenses (₹) | C6: =SUM('Expense Entry'!D2:D500) -> 15600 | H6: ='Product List'!A2 -> Notebook Set | I6: =IF(H6="","",SUMIFS('Sales Entry'!$C$2:$C$500,'Sales Entry'!$B$2:$B$500,H6,'Sales Entry'!$A$2:$A$500,TODAY())) -> 4 | J6: =IF(H6="","",SUMIFS('Sales Entry'!$E$2:$E$500,'Sales Entry'!$B$2:$B$500,H6,'Sales Entry'!$A$2:$A$500,TODAY())) -> 600
B7: Net Profit (₹) | C7: =C5-C6 -> -600 | H7: ='Product List'!A3 -> Water Bottle | I7: =IF(H7="","",SUMIFS('Sales Entry'!$C$2:$C$500,'Sales Entry'!$B$2:$B$500,H7,'Sales Entry'!$A$2:$A$500,TODAY())) -> 2 | J7: =IF(H7="","",SUMIFS('Sales Entry'!$E$2:$E$500,'Sales Entry'!$B$2:$B$500,H7,'Sales Entry'!$A$2:$A$500,TODAY())) -> 500
B8: Profit Margin (%) | C8: =IF(C5=0,0,C7/C5) -> -0.04 | H8: ='Product List'!A4 -> Backpack | I8: =IF(H8="","",SUMIFS('Sales Entry'!$C$2:$C$500,'Sales Entry'!$B$2:$B$500,H8,'Sales Entry'!$A$2:$A$500,TODAY())) -> 2 | J8: =IF(H8="","",SUMIFS('Sales Entry'!$E$2:$E$500,'Sales Entry'!$B$2:$B$500,H8,'Sales Entry'!$A$2:$A$500,TODAY())) -> 1800
H9: ='Product List'!A5 -> Pen Pack | I9: =IF(H9="","",SUMIFS('Sales Entry'!$C$2:$C$500,'Sales Entry'!$B$2:$B$500,H9,'Sales Entry'!$A$2:$A$500,TODAY())) -> 0 | J9: =IF(H9="","",SUMIFS('Sales Entry'!$E$2:$E$500,'Sales Entry'!$B$2:$B$500,H9,'Sales Entry'!$A$2:$A$500,TODAY())) -> 0
B10: Key Insights (Auto-Updates) | H10: ='Product List'!A6 -> 0 | I10: =IF(H10="","",SUMIFS('Sales Entry'!$C$2:$C$500,'Sales Entry'!$B$2:$B$500,H10,'Sales Entry'!$A$2:$A$500,TODAY())) | J10: =IF(H10="","",SUMIFS('Sales Entry'!$E$2:$E$500,'Sales Entry'!$B$2:$B$500,H10,'Sales Entry'!$A$2:$A$500,TODAY()))
B11: ="Top Seller: "&IFERROR(INDEX(H42:H71,MATCH(MAX(I42:I71),I42:I71,0)),"—")&" ("&MAX(I42:I71)&" units sold)" -> Top Seller: Notebook Set (34 units sold) | H11: ='Product List'!A7 -> 0 | I11: =IF(H11="","",SUMIFS('Sales Entry'!$C$2:$C$500,'Sales Entry'!$B$2:$B$500,H11,'Sales Entry'!$A$2:$A$500,TODAY())) | J11: =IF(H11="","",SUMIFS('Sales Entry'!$E$2:$E$500,'Sales Entry'!$B$2:$B$500,H11,'Sales Entry'!$A$2:$A$500,TODAY()))
B12: ="Highest Expense: "&IFERROR(INDEX(B14:B21,MATCH(MAX(C14:C21),C14:C21,0)),"—")&" (₹"&TEXT(MAX(C14:C21),"#,##0")&")" -> Highest Expense: Rent (₹10,000) | H12: ='Product List'!A8 -> 0 | I12: =IF(H12="","",SUMIFS('Sales Entry'!$C$2:$C$500,'Sales Entry'!$B$2:$B$500,H12,'Sales Entry'!$A$2:$A$500,TODAY())) | J12: =IF(H12="","",SUMIFS('Sales Entry'!$E$2:$E$500,'Sales Entry'!$B$2:$B$500,H12,'Sales Entry'!$A$2:$A$500,TODAY()))
B13: ="Status: "&IF(C7>0,"Profitable","Loss-making — review your expenses") -> Status: Loss-making — review your expenses | H13: ='Product List'!A9 -> 0 | I13: =IF(H13="","",SUMIFS('Sales Entry'!$C$2:$C$500,'Sales Entry'!$B$2:$B$500,H13,'Sales Entry'!$A$2:$A$500,TODAY())) | J13: =IF(H13="","",SUMIFS('Sales Entry'!$E$2:$E$500,'Sales Entry'!$B$2:$B$500,H13,'Sales Entry'!$A$2:$A$500,TODAY()))
B14: Expense Breakdown by Category | E14: Monthly Sales Summary | H14: ='Product List'!A10 -> 0 | I14: =IF(H14="","",SUMIFS('Sales Entry'!$C$2:$C$500,'Sales Entry'!$B$2:$B$500,H14,'Sales Entry'!$A$2:$A$500,TODAY())) | J14: =IF(H14="","",SUMIFS('Sales Entry'!$E$2:$E$500,'Sales Entry'!$B$2:$B$500,H14,'Sales Entry'!$A$2:$A$500,TODAY()))
B15: Category | C15: Total (₹) | E15: Month | F15: Sales (₹) | H15: ='Product List'!A11 -> 0 | I15: =IF(H15="","",SUMIFS('Sales Entry'!$C$2:$C$500,'Sales Entry'!$B$2:$B$500,H15,'Sales Entry'!$A$2:$A$500,TODAY())) | J15: =IF(H15="","",SUMIFS('Sales Entry'!$E$2:$E$500,'Sales Entry'!$B$2:$B$500,H15,'Sales Entry'!$A$2:$A$500,TODAY()))
B16: Rent | C16: =SUMIF('Expense Entry'!$B$2:$B$500,B16,'Expense Entry'!$D$2:$D$500) -> 10000 | E16: Jan | F16: =SUMPRODUCT(('Sales Entry'!$A$2:$A$500<>"")*(MONTH('Sales Entry'!$A$2:$A$500)=1)*'Sales Entry'!$C$2:$C$500*'Sales Entry'!$D$2:$D$500) -> 0 | H16: ='Product List'!A12 -> 0 | I16: =IF(H16="","",SUMIFS('Sales Entry'!$C$2:$C$500,'Sales Entry'!$B$2:$B$500,H16,'Sales Entry'!$A$2:$A$500,TODAY())) | J16: =IF(H16="","",SUMIFS('Sales Entry'!$E$2:$E$500,'Sales Entry'!$B$2:$B$500,H16,'Sales Entry'!$A$2:$A$500,TODAY()))
B17: Salaries | C17: =SUMIF('Expense Entry'!$B$2:$B$500,B17,'Expense Entry'!$D$2:$D$500) -> 0 | E17: Feb | F17: =SUMPRODUCT(('Sales Entry'!$A$2:$A$500<>"")*(MONTH('Sales Entry'!$A$2:$A$500)=2)*'Sales Entry'!$C$2:$C$500*'Sales Entry'!$D$2:$D$500) -> 0 | H17: ='Product List'!A13 -> 0 | I17: =IF(H17="","",SUMIFS('Sales Entry'!$C$2:$C$500,'Sales Entry'!$B$2:$B$500,H17,'Sales Entry'!$A$2:$A$500,TODAY())) | J17: =IF(H17="","",SUMIFS('Sales Entry'!$E$2:$E$500,'Sales Entry'!$B$2:$B$500,H17,'Sales Entry'!$A$2:$A$500,TODAY()))
B18: Inventory/Stock | C18: =SUMIF('Expense Entry'!$B$2:$B$500,B18,'Expense Entry'!$D$2:$D$500) -> 3000 | E18: Mar | F18: =SUMPRODUCT(('Sales Entry'!$A$2:$A$500<>"")*(MONTH('Sales Entry'!$A$2:$A$500)=3)*'Sales Entry'!$C$2:$C$500*'Sales Entry'!$D$2:$D$500) -> 0 | H18: ='Product List'!A14 -> 0 | I18: =IF(H18="","",SUMIFS('Sales Entry'!$C$2:$C$500,'Sales Entry'!$B$2:$B$500,H18,'Sales Entry'!$A$2:$A$500,TODAY())) | J18: =IF(H18="","",SUMIFS('Sales Entry'!$E$2:$E$500,'Sales Entry'!$B$2:$B$500,H18,'Sales Entry'!$A$2:$A$500,TODAY()))
B19: Utilities | C19: =SUMIF('Expense Entry'!$B$2:$B$500,B19,'Expense Entry'!$D$2:$D$500) -> 1200 | E19: Apr | F19: =SUMPRODUCT(('Sales Entry'!$A$2:$A$500<>"")*(MONTH('Sales Entry'!$A$2:$A$500)=4)*'Sales Entry'!$C$2:$C$500*'Sales Entry'!$D$2:$D$500) -> 0 | H19: ='Product List'!A15 -> 0 | I19: =IF(H19="","",SUMIFS('Sales Entry'!$C$2:$C$500,'Sales Entry'!$B$2:$B$500,H19,'Sales Entry'!$A$2:$A$500,TODAY())) | J19: =IF(H19="","",SUMIFS('Sales Entry'!$E$2:$E$500,'Sales Entry'!$B$2:$B$500,H19,'Sales Entry'!$A$2:$A$500,TODAY()))
B20: Marketing | C20: =SUMIF('Expense Entry'!$B$2:$B$500,B20,'Expense Entry'!$D$2:$D$500) -> 800 | E20: May | F20: =SUMPRODUCT(('Sales Entry'!$A$2:$A$500<>"")*(MONTH('Sales Entry'!$A$2:$A$500)=5)*'Sales Entry'!$C$2:$C$500*'Sales Entry'!$D$2:$D$500) -> 0 | H20: ='Product List'!A16 -> 0 | I20: =IF(H20="","",SUMIFS('Sales Entry'!$C$2:$C$500,'Sales Entry'!$B$2:$B$500,H20,'Sales Entry'!$A$2:$A$500,TODAY())) | J20: =IF(H20="","",SUMIFS('Sales Entry'!$E$2:$E$500,'Sales Entry'!$B$2:$B$500,H20,'Sales Entry'!$A$2:$A$500,TODAY()))
B21: Transport | C21: =SUMIF('Expense Entry'!$B$2:$B$500,B21,'Expense Entry'!$D$2:$D$500) -> 600 | E21: Jun | F21: =SUMPRODUCT(('Sales Entry'!$A$2:$A$500<>"")*(MONTH('Sales Entry'!$A$2:$A$500)=6)*'Sales Entry'!$C$2:$C$500*'Sales Entry'!$D$2:$D$500) -> 7800 | H21: ='Product List'!A17 -> 0 | I21: =IF(H21="","",SUMIFS('Sales Entry'!$C$2:$C$500,'Sales Entry'!$B$2:$B$500,H21,'Sales Entry'!$A$2:$A$500,TODAY())) | J21: =IF(H21="","",SUMIFS('Sales Entry'!$E$2:$E$500,'Sales Entry'!$B$2:$B$500,H21,'Sales Entry'!$A$2:$A$500,TODAY()))
B22: Maintenance | C22: =SUMIF('Expense Entry'!$B$2:$B$500,B22,'Expense Entry'!$D$2:$D$500) -> 0 | E22: Jul | F22: =SUMPRODUCT(('Sales Entry'!$A$2:$A$500<>"")*(MONTH('Sales Entry'!$A$2:$A$500)=7)*'Sales Entry'!$C$2:$C$500*'Sales Entry'!$D$2:$D$500) -> 7200 | H22: ='Product List'!A18 -> 0 | I22: =IF(H22="","",SUMIFS('Sales Entry'!$C$2:$C$500,'Sales Entry'!$B$2:$B$500,H22,'Sales Entry'!$A$2:$A$500,TODAY())) | J22: =IF(H22="","",SUMIFS('Sales Entry'!$E$2:$E$500,'Sales Entry'!$B$2:$B$500,H22,'Sales Entry'!$A$2:$A$500,TODAY()))
B23: Other | C23: =SUMIF('Expense Entry'!$B$2:$B$500,B23,'Expense Entry'!$D$2:$D$500) -> 0 | E23: Aug | F23: =SUMPRODUCT(('Sales Entry'!$A$2:$A$500<>"")*(MONTH('Sales Entry'!$A$2:$A$500)=8)*'Sales Entry'!$C$2:$C$500*'Sales Entry'!$D$2:$D$500) -> 0 | H23: ='Product List'!A19 -> 0 | I23: =IF(H23="","",SUMIFS('Sales Entry'!$C$2:$C$500,'Sales Entry'!$B$2:$B$500,H23,'Sales Entry'!$A$2:$A$500,TODAY())) | J23: =IF(H23="","",SUMIFS('Sales Entry'!$E$2:$E$500,'Sales Entry'!$B$2:$B$500,H23,'Sales Entry'!$A$2:$A$500,TODAY()))
E24: Sep | F24: =SUMPRODUCT(('Sales Entry'!$A$2:$A$500<>"")*(MONTH('Sales Entry'!$A$2:$A$500)=9)*'Sales Entry'!$C$2:$C$500*'Sales Entry'!$D$2:$D$500) -> 0 | H24: ='Product List'!A20 -> 0 | I24: =IF(H24="","",SUMIFS('Sales Entry'!$C$2:$C$500,'Sales Entry'!$B$2:$B$500,H24,'Sales Entry'!$A$2:$A$500,TODAY())) | J24: =IF(H24="","",SUMIFS('Sales Entry'!$E$2:$E$500,'Sales Entry'!$B$2:$B$500,H24,'Sales Entry'!$A$2:$A$500,TODAY()))
E25: Oct | F25: =SUMPRODUCT(('Sales Entry'!$A$2:$A$500<>"")*(MONTH('Sales Entry'!$A$2:$A$500)=10)*'Sales Entry'!$C$2:$C$500*'Sales Entry'!$D$2:$D$500) -> 0 | H25: ='Product List'!A21 -> 0 | I25: =IF(H25="","",SUMIFS('Sales Entry'!$C$2:$C$500,'Sales Entry'!$B$2:$B$500,H25,'Sales Entry'!$A$2:$A$500,TODAY())) | J25: =IF(H25="","",SUMIFS('Sales Entry'!$E$2:$E$500,'Sales Entry'!$B$2:$B$500,H25,'Sales Entry'!$A$2:$A$500,TODAY()))
E26: Nov | F26: =SUMPRODUCT(('Sales Entry'!$A$2:$A$500<>"")*(MONTH('Sales Entry'!$A$2:$A$500)=11)*'Sales Entry'!$C$2:$C$500*'Sales Entry'!$D$2:$D$500) -> 0 | H26: ='Product List'!A22 -> 0 | I26: =IF(H26="","",SUMIFS('Sales Entry'!$C$2:$C$500,'Sales Entry'!$B$2:$B$500,H26,'Sales Entry'!$A$2:$A$500,TODAY())) | J26: =IF(H26="","",SUMIFS('Sales Entry'!$E$2:$E$500,'Sales Entry'!$B$2:$B$500,H26,'Sales Entry'!$A$2:$A$500,TODAY()))
E27: Dec | F27: =SUMPRODUCT(('Sales Entry'!$A$2:$A$500<>"")*(MONTH('Sales Entry'!$A$2:$A$500)=12)*'Sales Entry'!$C$2:$C$500*'Sales Entry'!$D$2:$D$500) -> 0 | H27: ='Product List'!A23 -> 0 | I27: =IF(H27="","",SUMIFS('Sales Entry'!$C$2:$C$500,'Sales Entry'!$B$2:$B$500,H27,'Sales Entry'!$A$2:$A$500,TODAY())) | J27: =IF(H27="","",SUMIFS('Sales Entry'!$E$2:$E$500,'Sales Entry'!$B$2:$B$500,H27,'Sales Entry'!$A$2:$A$500,TODAY()))
H28: ='Product List'!A24 -> 0 | I28: =IF(H28="","",SUMIFS('Sales Entry'!$C$2:$C$500,'Sales Entry'!$B$2:$B$500,H28,'Sales Entry'!$A$2:$A$500,TODAY())) | J28: =IF(H28="","",SUMIFS('Sales Entry'!$E$2:$E$500,'Sales Entry'!$B$2:$B$500,H28,'Sales Entry'!$A$2:$A$500,TODAY()))
H29: ='Product List'!A25 -> 0 | I29: =IF(H29="","",SUMIFS('Sales Entry'!$C$2:$C$500,'Sales Entry'!$B$2:$B$500,H29,'Sales Entry'!$A$2:$A$500,TODAY())) | J29: =IF(H29="","",SUMIFS('Sales Entry'!$E$2:$E$500,'Sales Entry'!$B$2:$B$500,H29,'Sales Entry'!$A$2:$A$500,TODAY()))
H30: ='Product List'!A26 -> 0 | I30: =IF(H30="","",SUMIFS('Sales Entry'!$C$2:$C$500,'Sales Entry'!$B$2:$B$500,H30,'Sales Entry'!$A$2:$A$500,TODAY())) | J30: =IF(H30="","",SUMIFS('Sales Entry'!$E$2:$E$500,'Sales Entry'!$B$2:$B$500,H30,'Sales Entry'!$A$2:$A$500,TODAY()))
H31: ='Product List'!A27 -> 0 | I31: =IF(H31="","",SUMIFS('Sales Entry'!$C$2:$C$500,'Sales Entry'!$B$2:$B$500,H31,'Sales Entry'!$A$2:$A$500,TODAY())) | J31: =IF(H31="","",SUMIFS('Sales Entry'!$E$2:$E$500,'Sales Entry'!$B$2:$B$500,H31,'Sales Entry'!$A$2:$A$500,TODAY()))
H32: ='Product List'!A28 -> 0 | I32: =IF(H32="","",SUMIFS('Sales Entry'!$C$2:$C$500,'Sales Entry'!$B$2:$B$500,H32,'Sales Entry'!$A$2:$A$500,TODAY())) | J32: =IF(H32="","",SUMIFS('Sales Entry'!$E$2:$E$500,'Sales Entry'!$B$2:$B$500,H32,'Sales Entry'!$A$2:$A$500,TODAY()))
H33: ='Product List'!A29 -> 0 | I33: =IF(H33="","",SUMIFS('Sales Entry'!$C$2:$C$500,'Sales Entry'!$B$2:$B$500,H33,'Sales Entry'!$A$2:$A$500,TODAY())) | J33: =IF(H33="","",SUMIFS('Sales Entry'!$E$2:$E$500,'Sales Entry'!$B$2:$B$500,H33,'Sales Entry'!$A$2:$A$500,TODAY()))
H34: ='Product List'!A30 -> 0 | I34: =IF(H34="","",SUMIFS('Sales Entry'!$C$2:$C$500,'Sales Entry'!$B$2:$B$500,H34,'Sales Entry'!$A$2:$A$500,TODAY())) | J34: =IF(H34="","",SUMIFS('Sales Entry'!$E$2:$E$500,'Sales Entry'!$B$2:$B$500,H34,'Sales Entry'!$A$2:$A$500,TODAY()))
H35: ='Product List'!A31 -> 0 | I35: =IF(H35="","",SUMIFS('Sales Entry'!$C$2:$C$500,'Sales Entry'!$B$2:$B$500,H35,'Sales Entry'!$A$2:$A$500,TODAY())) | J35: =IF(H35="","",SUMIFS('Sales Entry'!$E$2:$E$500,'Sales Entry'!$B$2:$B$500,H35,'Sales Entry'!$A$2:$A$500,TODAY()))
H37: Total Today | I37: =SUMIFS('Sales Entry'!$C$2:$C$500,'Sales Entry'!$A$2:$A$500,TODAY()) -> 8 | J37: =SUMIFS('Sales Entry'!$E$2:$E$500,'Sales Entry'!$A$2:$A$500,TODAY()) -> 2900
H40: All-Time Product Totals
H41: Product | I41: Total Qty Sold | J41: Total Revenue (₹)
H42: ='Product List'!A2 -> Notebook Set | I42: =IF(H42="","",SUMIF('Sales Entry'!$B$2:$B$500,H42,'Sales Entry'!$C$2:$C$500)) -> 34 | J42: =IF(H42="","",SUMIF('Sales Entry'!$B$2:$B$500,H42,'Sales Entry'!$E$2:$E$500)) -> 5100
H43: ='Product List'!A3 -> Water Bottle | I43: =IF(H43="","",SUMIF('Sales Entry'!$B$2:$B$500,H43,'Sales Entry'!$C$2:$C$500)) -> 18 | J43: =IF(H43="","",SUMIF('Sales Entry'!$B$2:$B$500,H43,'Sales Entry'!$E$2:$E$500)) -> 4500
H44: ='Product List'!A4 -> Backpack | I44: =IF(H44="","",SUMIF('Sales Entry'!$B$2:$B$500,H44,'Sales Entry'!$C$2:$C$500)) -> 5 | J44: =IF(H44="","",SUMIF('Sales Entry'!$B$2:$B$500,H44,'Sales Entry'!$E$2:$E$500)) -> 4500
H45: ='Product List'!A5 -> Pen Pack | I45: =IF(H45="","",SUMIF('Sales Entry'!$B$2:$B$500,H45,'Sales Entry'!$C$2:$C$500)) -> 15 | J45: =IF(H45="","",SUMIF('Sales Entry'!$B$2:$B$500,H45,'Sales Entry'!$E$2:$E$500)) -> 900
...
